Workbook

Sheet Statement Data
A1: MICRON TECHNOLOGY INC (MU) — Statement data ($m)
B2: FY2024 | C2: FY2025
A3: Revenue | B3: 25111 | C3: 37378
A4: Cost of goods sold | B4: 19498 | C4: 22505
A5: Gross profit | B5: 5613 | C5: 14873
A6: Operating income (EBIT) | B6: 1304 | C6: 9770
A7: Depreciation & amortisation | B7: 7780 | C7: 8352
A8: SG&A | B8: 1129 | C8: 1205
A9: Net income | B9: 778 | C9: 8539
A10: Cash from operations | B10: 8507 | C10: 17525
A11: Capex | B11: 8386 | C11: 15857
A12: Total assets | B12: 69416 | C12: 82798
A13: Current assets | B13: 24372 | C13: 28841
A14: Current liabilities | B14: 9248 | C14: 11454
... A18: Receivables | B18: 5419 | C18: 7163
A19: PP&E (net)
A20: Long-term debt | B20: 11343 | C20: 11533
A21: Short-term debt | B21: 431 | C21: 560
A22: Cash & equivalents | B22: 7041 | C22: 9642
A23: Diluted shares (m) | B23: 1118 | C23: 1125
A25: Market cap ($m) | B25: 1275738.8
A26: WACC | B26: 0.142
A27: Tax rate | B27: 0.21

Sheet Calculations
A1: Calculations (live formulas → Statement Data)
A3: PROFITABILITY
A4: Gross margin | B4: =IFERROR('Statement Data'!C5/'Statement Data'!C3,"n/a") | C4: Gross profit / Revenue
A5: Operating margin | B5: =IFERROR('Statement Data'!C6/'Statement Data'!C3,"n/a") | C5: EBIT / Revenue
A6: Net margin | B6: =IFERROR('Statement Data'!C9/'Statement Data'!C3,"n/a") | C6: Net income / Revenue
A7: ROA | B7: =IFERROR('Statement Data'!C9/'Statement Data'!C12,"n/a") | C7: Net income / Total assets
A8: ROE | B8: =IFERROR('Statement Data'!C9/'Statement Data'!C16,"n/a") | C8: Net income / Equity
A9: DUPONT (ROE = margin x turnover x leverage)
A10: Net margin | B10: =IFERROR('Statement Data'!C9/'Statement Data'!C3,"n/a")
A11: Asset turnover | B11: =IFERROR('Statement Data'!C3/'Statement Data'!C12,"n/a") | C11: Revenue / Total assets
A12: Equity multiplier | B12: =IFERROR('Statement Data'!C12/'Statement Data'!C16,"n/a") | C12: Total assets / Equity
A13: ROE (DuPont) | B13: =IFERROR(B10*B11*B12,"n/a") | C13: =the three above multiplied
A14: VALUE CREATION
A15: ROIC | B15: =IFERROR('Statement Data'!C6*(1-'Statement Data'!B27)/('Statement Data'!C20+'Statement Data'!C21+'Statement Data'!C16-'Statement Data'!C22),"n/a") | C15: NOPAT / (total debt + equity - cash)
A16: WACC | B16: ='Statement Data'!B26 | C16: cost of capital (input)
A17: ROIC - WACC spread | B17: =IFERROR(B15-'Statement Data'!B26,"n/a") | C17: >0 = creates value
A18: BALANCE-SHEET HEALTH
A19: Current ratio | B19: =IFERROR('Statement Data'!C13/'Statement Data'!C14,"n/a")
A20: LT debt / Equity | B20: =IFERROR('Statement Data'!C20/'Statement Data'!C16,"n/a")
A21: Net debt / EBITDA | B21: =IFERROR(('Statement Data'!C20+'Statement Data'!C21-'Statement Data'!C22)/('Statement Data'!C6+'Statement Data'!C7),"n/a")
A22: PIOTROSKI F-SCORE (1 point each)
A23: Positive ROA | B23: =IFERROR(IF('Statement Data'!C9/'Statement Data'!C12>0,1,0),0) | C23: profitable on assets
A24: Positive CFO | B24: =IF('Statement Data'!C10>0,1,0) | C24: operating cash positive
A25: Rising ROA | B25: =IFERROR(IF('Statement Data'!C9/'Statement Data'!C12>'Statement Data'!B9/'Statement Data'!B12,1,0),0)
A26: CFO > Net income | B26: =IFERROR(IF('Statement Data'!C10/'Statement Data'!C12>'Statement Data'!C9/'Statement Data'!C12,1,0),0) | C26: accrual quality
A27: Lower leverage | B27: =IFERROR(IF('Statement Data'!C20/'Statement Data'!C12<'Statement Data'!B20/'Statement Data'!B12,1,0),0)
A28: Higher current ratio | B28: =IFERROR(IF('Statement Data'!C13/'Statement Data'!C14>'Statement Data'!B13/'Statement Data'!B14,1,0),0)
A29: No dilution | B29: =IFERROR(IF('Statement Data'!C23<='Statement Data'!B23*1.001,1,0),0) | C29: shares not up
A30: Higher gross margin | B30: =IFERROR(IF('Statement Data'!C5/'Statement Data'!C3>'Statement Data'!B5/'Statement Data'!B3,1,0),0)
A31: Higher asset turnover | B31: =IFERROR(IF('Statement Data'!C3/'Statement Data'!C12>'Statement Data'!B3/'Statement Data'!B12,1,0),0)
A32: F-Score (/9) | B32: =SUM(B23:B31) | C32: 7-9 strong, 0-3 weak
A33: ALTMAN Z-SCORE
A34: Altman Z | B34: =IFERROR(1.2*('Statement Data'!C13-'Statement Data'!C14)/'Statement Data'!C12+1.4*'Statement Data'!C17/'Statement Data'!C12+3.3*'Statement Data'!C6/'Statement Data'!C12+0.6*'Statement Data'!B25/'Statement Data'!C15+'Statement Data'!C3/'Statement Data'!C12,"n/a") | C34: >2.99 safe, <1.81 distress
A35: BENEISH M-SCORE (>-1.78 = possible manipulation)
A36: DSRI (receivables) | B36: =IFERROR(('Statement Data'!C18/'Statement Data'!C3)/('Statement Data'!B18/'Statement Data'!B3),"n/a")
A37: GMI (gross margin) | B37: =IFERROR(('Statement Data'!B5/'Statement Data'!B3)/('Statement Data'!C5/'Statement Data'!C3),"n/a")
A38: AQI (asset quality) | B38: =IFERROR((1-('Statement Data'!C13+'Statement Data'!C19)/'Statement Data'!C12)/(1-('Statement Data'!B13+'Statement Data'!B19)/'Statement Data'!B12),"n/a")
A39: SGI (sales growth) | B39: =IFERROR('Statement Data'!C3/'Statement Data'!B3,"n/a")
A40: DEPI (depreciation) | B40: =IFERROR(('Statement Data'!B7/('Statement Data'!B7+'Statement Data'!B19))/('Statement Data'!C7/('Statement Data'!C7+'Statement Data'!C19)),"n/a")
A41: SGAI (SG&A) | B41: =IFERROR(('Statement Data'!C8/'Statement Data'!C3)/('Statement Data'!B8/'Statement Data'!B3),"n/a")
...
